[2024-09-23T15:05:20Z] DEBUG    - Logging set up successfully
[2024-09-23T15:05:20Z] DEBUG    - Running generate: Namespace(version=False, subparser_name='generate', command=<function generate at 0x11296b240>, verbose=0, endpoint_url=None, region=None, local_only=False, target_schemas=[], profile=None)
[2024-09-23T15:05:20Z] DEBUG    - Root directory: /Users/florinmanaila/Documents/Redis-CloudFormationResourceType
[2024-09-23T15:05:20Z] DEBUG    - Loading project file '/Users/florinmanaila/Documents/Redis-CloudFormationResourceType/.rpdk-config'
[2024-09-23T15:05:20Z] DEBUG    - Project file /Users/florinmanaila/Documents/Redis-CloudFormationResourceType/.rpdk-config not found. Have you run 'init' or in a wrong directory?
Traceback (most recent call last):
  File "/opt/homebrew/lib/python3.11/site-packages/rpdk/core/project.py", line 621, in load
    self.load_settings()
  File "/opt/homebrew/lib/python3.11/site-packages/rpdk/core/project.py", line 279, in load_settings
    with self.settings_path.open("r", encoding="utf-8") as f:
         ^^^^^^^^^^^^^^^^^^^^^^^^^^^^^^^^^^^^^^^^^^^^^^
  File "/opt/homebrew/Cellar/python@3.11/3.11.9_1/Frameworks/Python.framework/Versions/3.11/lib/python3.11/pathlib.py", line 1044, in open
    return io.open(self, mode, buffering, encoding, errors, newline)
           ^^^^^^^^^^^^^^^^^^^^^^^^^^^^^^^^^^^^^^^^^^^^^^^^^^^^^^^^^
FileNotFoundError: [Errno 2] No such file or directory: '/Users/florinmanaila/Documents/Redis-CloudFormationResourceType/.rpdk-config'
[2024-09-23T15:05:20Z] DEBUG    - Caught exit recommendation
Traceback (most recent call last):
  File "/opt/homebrew/lib/python3.11/site-packages/rpdk/core/project.py", line 621, in load
    self.load_settings()
  File "/opt/homebrew/lib/python3.11/site-packages/rpdk/core/project.py", line 279, in load_settings
    with self.settings_path.open("r", encoding="utf-8") as f:
         ^^^^^^^^^^^^^^^^^^^^^^^^^^^^^^^^^^^^^^^^^^^^^^
  File "/opt/homebrew/Cellar/python@3.11/3.11.9_1/Frameworks/Python.framework/Versions/3.11/lib/python3.11/pathlib.py", line 1044, in open
    return io.open(self, mode, buffering, encoding, errors, newline)
           ^^^^^^^^^^^^^^^^^^^^^^^^^^^^^^^^^^^^^^^^^^^^^^^^^^^^^^^^^
FileNotFoundError: [Errno 2] No such file or directory: '/Users/florinmanaila/Documents/Redis-CloudFormationResourceType/.rpdk-config'

The above exception was the direct cause of the following exception:

Traceback (most recent call last):
  File "/opt/homebrew/lib/python3.11/site-packages/rpdk/core/cli.py", line 105, in main
    args.command(args)
  File "/opt/homebrew/lib/python3.11/site-packages/rpdk/core/generate.py", line 14, in generate
    project.load()
  File "/opt/homebrew/lib/python3.11/site-packages/rpdk/core/project.py", line 623, in load
    self._raise_invalid_project(
  File "/opt/homebrew/lib/python3.11/site-packages/rpdk/core/project.py", line 274, in _raise_invalid_project
    raise InvalidProjectError(msg) from e
rpdk.core.exceptions.InvalidProjectError: Project file /Users/florinmanaila/Documents/Redis-CloudFormationResourceType/.rpdk-config not found. Have you run 'init' or in a wrong directory?
[2024-09-23T15:05:20Z] CRITICAL - Project file /Users/florinmanaila/Documents/Redis-CloudFormationResourceType/.rpdk-config not found. Have you run 'init' or in a wrong directory?
[2024-09-23T15:05:24Z] DEBUG    - Logging set up successfully
[2024-09-23T15:05:24Z] DEBUG    - Running None: Namespace(version=False, subparser_name=None, command=<function init at 0x114318fe0>, verbose=0, force=False, type_name=None, artifact_type=None, endpoint_url=None, region=None, target_schemas=[], profile=None)
[2024-09-23T15:05:24Z] DEBUG    - Root directory: /Users/florinmanaila/Documents/Redis-CloudFormationResourceType
[2024-09-23T15:05:24Z] WARNING  - Initializing new project
[2024-09-23T15:05:24Z] DEBUG    - Loading project file '/Users/florinmanaila/Documents/Redis-CloudFormationResourceType/.rpdk-config'
[2024-09-24T07:34:44Z] DEBUG    - Logging set up successfully
[2024-09-24T07:34:44Z] DEBUG    - Running generate: Namespace(version=False, subparser_name='generate', command=<function generate at 0x10646b240>, verbose=0, endpoint_url=None, region=None, local_only=False, target_schemas=[], profile=None)
[2024-09-24T07:34:44Z] DEBUG    - Root directory: /Users/florinmanaila/Documents/Redis-CloudFormationResourceType
[2024-09-24T07:34:44Z] DEBUG    - Loading project file '/Users/florinmanaila/Documents/Redis-CloudFormationResourceType/.rpdk-config'
[2024-09-24T07:34:44Z] DEBUG    - Project file /Users/florinmanaila/Documents/Redis-CloudFormationResourceType/.rpdk-config not found. Have you run 'init' or in a wrong directory?
Traceback (most recent call last):
  File "/opt/homebrew/lib/python3.11/site-packages/rpdk/core/project.py", line 621, in load
    self.load_settings()
  File "/opt/homebrew/lib/python3.11/site-packages/rpdk/core/project.py", line 279, in load_settings
    with self.settings_path.open("r", encoding="utf-8") as f:
         ^^^^^^^^^^^^^^^^^^^^^^^^^^^^^^^^^^^^^^^^^^^^^^
  File "/opt/homebrew/Cellar/python@3.11/3.11.9_1/Frameworks/Python.framework/Versions/3.11/lib/python3.11/pathlib.py", line 1044, in open
    return io.open(self, mode, buffering, encoding, errors, newline)
           ^^^^^^^^^^^^^^^^^^^^^^^^^^^^^^^^^^^^^^^^^^^^^^^^^^^^^^^^^
FileNotFoundError: [Errno 2] No such file or directory: '/Users/florinmanaila/Documents/Redis-CloudFormationResourceType/.rpdk-config'
[2024-09-24T07:34:44Z] DEBUG    - Caught exit recommendation
Traceback (most recent call last):
  File "/opt/homebrew/lib/python3.11/site-packages/rpdk/core/project.py", line 621, in load
    self.load_settings()
  File "/opt/homebrew/lib/python3.11/site-packages/rpdk/core/project.py", line 279, in load_settings
    with self.settings_path.open("r", encoding="utf-8") as f:
         ^^^^^^^^^^^^^^^^^^^^^^^^^^^^^^^^^^^^^^^^^^^^^^
  File "/opt/homebrew/Cellar/python@3.11/3.11.9_1/Frameworks/Python.framework/Versions/3.11/lib/python3.11/pathlib.py", line 1044, in open
    return io.open(self, mode, buffering, encoding, errors, newline)
           ^^^^^^^^^^^^^^^^^^^^^^^^^^^^^^^^^^^^^^^^^^^^^^^^^^^^^^^^^
FileNotFoundError: [Errno 2] No such file or directory: '/Users/florinmanaila/Documents/Redis-CloudFormationResourceType/.rpdk-config'

The above exception was the direct cause of the following exception:

Traceback (most recent call last):
  File "/opt/homebrew/lib/python3.11/site-packages/rpdk/core/cli.py", line 105, in main
    args.command(args)
  File "/opt/homebrew/lib/python3.11/site-packages/rpdk/core/generate.py", line 14, in generate
    project.load()
  File "/opt/homebrew/lib/python3.11/site-packages/rpdk/core/project.py", line 623, in load
    self._raise_invalid_project(
  File "/opt/homebrew/lib/python3.11/site-packages/rpdk/core/project.py", line 274, in _raise_invalid_project
    raise InvalidProjectError(msg) from e
rpdk.core.exceptions.InvalidProjectError: Project file /Users/florinmanaila/Documents/Redis-CloudFormationResourceType/.rpdk-config not found. Have you run 'init' or in a wrong directory?
[2024-09-24T07:34:44Z] CRITICAL - Project file /Users/florinmanaila/Documents/Redis-CloudFormationResourceType/.rpdk-config not found. Have you run 'init' or in a wrong directory?
[2024-09-24T07:34:47Z] DEBUG    - Logging set up successfully
[2024-09-24T07:34:47Z] DEBUG    - Running submit: Namespace(version=False, subparser_name='submit', command=<function submit at 0x109d14900>, verbose=0, dry_run=False, endpoint_url=None, region=None, set_default=False, profile=None, role_arn=None, use_role=True, use_docker=False, no_docker=False)
[2024-09-24T07:34:47Z] DEBUG    - Root directory: /Users/florinmanaila/Documents/Redis-CloudFormationResourceType
[2024-09-24T07:34:47Z] DEBUG    - Loading project file '/Users/florinmanaila/Documents/Redis-CloudFormationResourceType/.rpdk-config'
[2024-09-24T07:34:47Z] DEBUG    - Project file /Users/florinmanaila/Documents/Redis-CloudFormationResourceType/.rpdk-config not found. Have you run 'init' or in a wrong directory?
Traceback (most recent call last):
  File "/opt/homebrew/lib/python3.11/site-packages/rpdk/core/project.py", line 621, in load
    self.load_settings()
  File "/opt/homebrew/lib/python3.11/site-packages/rpdk/core/project.py", line 279, in load_settings
    with self.settings_path.open("r", encoding="utf-8") as f:
         ^^^^^^^^^^^^^^^^^^^^^^^^^^^^^^^^^^^^^^^^^^^^^^
  File "/opt/homebrew/Cellar/python@3.11/3.11.9_1/Frameworks/Python.framework/Versions/3.11/lib/python3.11/pathlib.py", line 1044, in open
    return io.open(self, mode, buffering, encoding, errors, newline)
           ^^^^^^^^^^^^^^^^^^^^^^^^^^^^^^^^^^^^^^^^^^^^^^^^^^^^^^^^^
FileNotFoundError: [Errno 2] No such file or directory: '/Users/florinmanaila/Documents/Redis-CloudFormationResourceType/.rpdk-config'
[2024-09-24T07:34:47Z] DEBUG    - Caught exit recommendation
Traceback (most recent call last):
  File "/opt/homebrew/lib/python3.11/site-packages/rpdk/core/project.py", line 621, in load
    self.load_settings()
  File "/opt/homebrew/lib/python3.11/site-packages/rpdk/core/project.py", line 279, in load_settings
    with self.settings_path.open("r", encoding="utf-8") as f:
         ^^^^^^^^^^^^^^^^^^^^^^^^^^^^^^^^^^^^^^^^^^^^^^
  File "/opt/homebrew/Cellar/python@3.11/3.11.9_1/Frameworks/Python.framework/Versions/3.11/lib/python3.11/pathlib.py", line 1044, in open
    return io.open(self, mode, buffering, encoding, errors, newline)
           ^^^^^^^^^^^^^^^^^^^^^^^^^^^^^^^^^^^^^^^^^^^^^^^^^^^^^^^^^
FileNotFoundError: [Errno 2] No such file or directory: '/Users/florinmanaila/Documents/Redis-CloudFormationResourceType/.rpdk-config'

The above exception was the direct cause of the following exception:

Traceback (most recent call last):
  File "/opt/homebrew/lib/python3.11/site-packages/rpdk/core/cli.py", line 105, in main
    args.command(args)
  File "/opt/homebrew/lib/python3.11/site-packages/rpdk/core/submit.py", line 14, in submit
    project.load()
  File "/opt/homebrew/lib/python3.11/site-packages/rpdk/core/project.py", line 623, in load
    self._raise_invalid_project(
  File "/opt/homebrew/lib/python3.11/site-packages/rpdk/core/project.py", line 274, in _raise_invalid_project
    raise InvalidProjectError(msg) from e
rpdk.core.exceptions.InvalidProjectError: Project file /Users/florinmanaila/Documents/Redis-CloudFormationResourceType/.rpdk-config not found. Have you run 'init' or in a wrong directory?
[2024-09-24T07:34:47Z] CRITICAL - Project file /Users/florinmanaila/Documents/Redis-CloudFormationResourceType/.rpdk-config not found. Have you run 'init' or in a wrong directory?
[2024-09-30T08:37:50Z] DEBUG    - Logging set up successfully
[2024-09-30T08:37:50Z] DEBUG    - Running generate: Namespace(version=False, subparser_name='generate', command=<function generate at 0x107f6b240>, verbose=0, endpoint_url=None, region=None, local_only=False, target_schemas=[], profile=None)
[2024-09-30T08:37:50Z] DEBUG    - Root directory: /Users/florinmanaila/Documents/Redis-CloudFormationResourceType
[2024-09-30T08:37:50Z] DEBUG    - Loading project file '/Users/florinmanaila/Documents/Redis-CloudFormationResourceType/.rpdk-config'
[2024-09-30T08:37:50Z] DEBUG    - Project file /Users/florinmanaila/Documents/Redis-CloudFormationResourceType/.rpdk-config not found. Have you run 'init' or in a wrong directory?
Traceback (most recent call last):
  File "/opt/homebrew/lib/python3.11/site-packages/rpdk/core/project.py", line 621, in load
    self.load_settings()
  File "/opt/homebrew/lib/python3.11/site-packages/rpdk/core/project.py", line 279, in load_settings
    with self.settings_path.open("r", encoding="utf-8") as f:
         ^^^^^^^^^^^^^^^^^^^^^^^^^^^^^^^^^^^^^^^^^^^^^^
  File "/opt/homebrew/Cellar/python@3.11/3.11.9_1/Frameworks/Python.framework/Versions/3.11/lib/python3.11/pathlib.py", line 1044, in open
    return io.open(self, mode, buffering, encoding, errors, newline)
           ^^^^^^^^^^^^^^^^^^^^^^^^^^^^^^^^^^^^^^^^^^^^^^^^^^^^^^^^^
FileNotFoundError: [Errno 2] No such file or directory: '/Users/florinmanaila/Documents/Redis-CloudFormationResourceType/.rpdk-config'
[2024-09-30T08:37:50Z] DEBUG    - Caught exit recommendation
Traceback (most recent call last):
  File "/opt/homebrew/lib/python3.11/site-packages/rpdk/core/project.py", line 621, in load
    self.load_settings()
  File "/opt/homebrew/lib/python3.11/site-packages/rpdk/core/project.py", line 279, in load_settings
    with self.settings_path.open("r", encoding="utf-8") as f:
         ^^^^^^^^^^^^^^^^^^^^^^^^^^^^^^^^^^^^^^^^^^^^^^
  File "/opt/homebrew/Cellar/python@3.11/3.11.9_1/Frameworks/Python.framework/Versions/3.11/lib/python3.11/pathlib.py", line 1044, in open
    return io.open(self, mode, buffering, encoding, errors, newline)
           ^^^^^^^^^^^^^^^^^^^^^^^^^^^^^^^^^^^^^^^^^^^^^^^^^^^^^^^^^
FileNotFoundError: [Errno 2] No such file or directory: '/Users/florinmanaila/Documents/Redis-CloudFormationResourceType/.rpdk-config'

The above exception was the direct cause of the following exception:

Traceback (most recent call last):
  File "/opt/homebrew/lib/python3.11/site-packages/rpdk/core/cli.py", line 105, in main
    args.command(args)
  File "/opt/homebrew/lib/python3.11/site-packages/rpdk/core/generate.py", line 14, in generate
    project.load()
  File "/opt/homebrew/lib/python3.11/site-packages/rpdk/core/project.py", line 623, in load
    self._raise_invalid_project(
  File "/opt/homebrew/lib/python3.11/site-packages/rpdk/core/project.py", line 274, in _raise_invalid_project
    raise InvalidProjectError(msg) from e
rpdk.core.exceptions.InvalidProjectError: Project file /Users/florinmanaila/Documents/Redis-CloudFormationResourceType/.rpdk-config not found. Have you run 'init' or in a wrong directory?
[2024-09-30T08:37:50Z] CRITICAL - Project file /Users/florinmanaila/Documents/Redis-CloudFormationResourceType/.rpdk-config not found. Have you run 'init' or in a wrong directory?
